[2024-01-26T19:33:57.534+0000] {taskinstance.py:1159} INFO - Dependencies all met for dep_context=non-requeueable deps ti=<TaskInstance: test_dag.test_redshift scheduled__2023-10-18T00:00:00+00:00 [queued]>
[2024-01-26T19:33:57.542+0000] {taskinstance.py:1159} INFO - Dependencies all met for dep_context=requeueable deps ti=<TaskInstance: test_dag.test_redshift scheduled__2023-10-18T00:00:00+00:00 [queued]>
[2024-01-26T19:33:57.544+0000] {taskinstance.py:1361} INFO - Starting attempt 1 of 1
[2024-01-26T19:33:57.595+0000] {taskinstance.py:1382} INFO - Executing <Task(RedshiftDataOperator): test_redshift> on 2023-10-18 00:00:00+00:00
[2024-01-26T19:33:57.599+0000] {standard_task_runner.py:57} INFO - Started process 855 to run task
[2024-01-26T19:33:57.602+0000] {standard_task_runner.py:84} INFO - Running: ['***', 'tasks', 'run', 'test_dag', 'test_redshift', 'scheduled__2023-10-18T00:00:00+00:00', '--job-id', '284', '--raw', '--subdir', 'DAGS_FOLDER/test_dag.py', '--cfg-path', '/tmp/tmp8d0i78c2']
[2024-01-26T19:33:57.603+0000] {standard_task_runner.py:85} INFO - Job 284: Subtask test_redshift
[2024-01-26T19:33:57.634+0000] {task_command.py:416} INFO - Running <TaskInstance: test_dag.test_redshift scheduled__2023-10-18T00:00:00+00:00 [running]> on host d6d47e6adee9
[2024-01-26T19:33:57.676+0000] {taskinstance.py:1662} INFO - Exporting env vars: AIRFLOW_CTX_DAG_OWNER='***' AIRFLOW_CTX_DAG_ID='test_dag' AIRFLOW_CTX_TASK_ID='test_redshift' AIRFLOW_CTX_EXECUTION_DATE='2023-10-18T00:00:00+00:00' AIRFLOW_CTX_TRY_NUMBER='1' AIRFLOW_CTX_DAG_RUN_ID='scheduled__2023-10-18T00:00:00+00:00'
[2024-01-26T19:33:57.680+0000] {redshift_data.py:122} INFO - Executing statement: 
                select *
                from marina.applicant a 
                limit 10 
                
[2024-01-26T19:33:57.685+0000] {base_aws.py:581} WARNING - Unable to find AWS Connection ID 'aws_default', switching to empty.
[2024-01-26T19:33:57.686+0000] {base_aws.py:161} INFO - No connection ID provided. Fallback on boto3 credential strategy (region_name=None). See: https://boto3.amazonaws.com/v1/documentation/api/latest/guide/configuration.html
[2024-01-26T19:33:59.871+0000] {taskinstance.py:1937} ERROR - Task failed with exception
Traceback (most recent call last):
  File "/home/airflow/.local/lib/python3.8/site-packages/airflow/providers/amazon/aws/operators/redshift_data.py", line 124, in execute
    self.statement_id = self.hook.execute_query(
  File "/home/airflow/.local/lib/python3.8/site-packages/airflow/providers/amazon/aws/hooks/redshift_data.py", line 99, in execute_query
    resp = self.conn.execute_statement(**trim_none_values(kwargs))
  File "/usr/local/lib/python3.8/functools.py", line 967, in __get__
    val = self.func(instance)
  File "/home/airflow/.local/lib/python3.8/site-packages/airflow/providers/amazon/aws/hooks/base_aws.py", line 704, in conn
    return self.get_client_type(region_name=self.region_name)
  File "/home/airflow/.local/lib/python3.8/site-packages/airflow/providers/amazon/aws/hooks/base_aws.py", line 674, in get_client_type
    return session.client(
  File "/home/airflow/.local/lib/python3.8/site-packages/boto3/session.py", line 299, in client
    return self._session.create_client(
  File "/home/airflow/.local/lib/python3.8/site-packages/botocore/session.py", line 997, in create_client
    client = client_creator.create_client(
  File "/home/airflow/.local/lib/python3.8/site-packages/botocore/client.py", line 159, in create_client
    client_args = self._get_client_args(
  File "/home/airflow/.local/lib/python3.8/site-packages/botocore/client.py", line 490, in _get_client_args
    return args_creator.get_client_args(
  File "/home/airflow/.local/lib/python3.8/site-packages/botocore/args.py", line 100, in get_client_args
    final_args = self.compute_client_args(
  File "/home/airflow/.local/lib/python3.8/site-packages/botocore/args.py", line 219, in compute_client_args
    endpoint_config = self._compute_endpoint_config(
  File "/home/airflow/.local/lib/python3.8/site-packages/botocore/args.py", line 368, in _compute_endpoint_config
    return self._resolve_endpoint(**resolve_endpoint_kwargs)
  File "/home/airflow/.local/lib/python3.8/site-packages/botocore/args.py", line 473, in _resolve_endpoint
    return endpoint_bridge.resolve(
  File "/home/airflow/.local/lib/python3.8/site-packages/botocore/client.py", line 595, in resolve
    resolved = self.endpoint_resolver.construct_endpoint(
  File "/home/airflow/.local/lib/python3.8/site-packages/botocore/regions.py", line 229, in construct_endpoint
    result = self._endpoint_for_partition(
  File "/home/airflow/.local/lib/python3.8/site-packages/botocore/regions.py", line 277, in _endpoint_for_partition
    raise NoRegionError()
botocore.exceptions.NoRegionError: You must specify a region.
[2024-01-26T19:33:59.879+0000] {taskinstance.py:1400} INFO - Marking task as FAILED. dag_id=test_dag, task_id=test_redshift, execution_date=20231018T000000, start_date=20240126T193357, end_date=20240126T193359
[2024-01-26T19:33:59.886+0000] {standard_task_runner.py:104} ERROR - Failed to execute job 284 for task test_redshift (You must specify a region.; 855)
[2024-01-26T19:33:59.914+0000] {local_task_job_runner.py:228} INFO - Task exited with return code 1
[2024-01-26T19:33:59.927+0000] {taskinstance.py:2778} INFO - 0 downstream tasks scheduled from follow-on schedule check
