[2024-01-27T00:00:01.247+0000] {taskinstance.py:1159} INFO - Dependencies all met for dep_context=non-requeueable deps ti=<TaskInstance: test_dag.test_redshift scheduled__2024-01-26T00:00:00+00:00 [queued]>
[2024-01-27T00:00:01.252+0000] {taskinstance.py:1159} INFO - Dependencies all met for dep_context=requeueable deps ti=<TaskInstance: test_dag.test_redshift scheduled__2024-01-26T00:00:00+00:00 [queued]>
[2024-01-27T00:00:01.253+0000] {taskinstance.py:1361} INFO - Starting attempt 1 of 1
[2024-01-27T00:00:01.259+0000] {taskinstance.py:1382} INFO - Executing <Task(RedshiftDataOperator): test_redshift> on 2024-01-26 00:00:00+00:00
[2024-01-27T00:00:01.262+0000] {standard_task_runner.py:57} INFO - Started process 5149 to run task
[2024-01-27T00:00:01.265+0000] {standard_task_runner.py:84} INFO - Running: ['***', 'tasks', 'run', 'test_dag', 'test_redshift', 'scheduled__2024-01-26T00:00:00+00:00', '--job-id', '389', '--raw', '--subdir', 'DAGS_FOLDER/test_dag.py', '--cfg-path', '/tmp/tmptjtxweiu']
[2024-01-27T00:00:01.265+0000] {standard_task_runner.py:85} INFO - Job 389: Subtask test_redshift
[2024-01-27T00:00:01.292+0000] {task_command.py:416} INFO - Running <TaskInstance: test_dag.test_redshift scheduled__2024-01-26T00:00:00+00:00 [running]> on host d6d47e6adee9
[2024-01-27T00:00:01.330+0000] {taskinstance.py:1662} INFO - Exporting env vars: AIRFLOW_CTX_DAG_OWNER='***' AIRFLOW_CTX_DAG_ID='test_dag' AIRFLOW_CTX_TASK_ID='test_redshift' AIRFLOW_CTX_EXECUTION_DATE='2024-01-26T00:00:00+00:00' AIRFLOW_CTX_TRY_NUMBER='1' AIRFLOW_CTX_DAG_RUN_ID='scheduled__2024-01-26T00:00:00+00:00'
[2024-01-27T00:00:01.331+0000] {redshift_data.py:122} INFO - Executing statement: 
                select *
                from marina.applicant a 
                limit 10; 
                
[2024-01-27T00:00:01.335+0000] {base_aws.py:581} WARNING - Unable to find AWS Connection ID 'aws_default', switching to empty.
[2024-01-27T00:00:01.335+0000] {base_aws.py:161} INFO - No connection ID provided. Fallback on boto3 credential strategy (region_name='us-west-2'). See: https://boto3.amazonaws.com/v1/documentation/api/latest/guide/configuration.html
[2024-01-27T00:00:03.546+0000] {taskinstance.py:1937} ERROR - Task failed with exception
Traceback (most recent call last):
  File "/home/airflow/.local/lib/python3.8/site-packages/airflow/providers/amazon/aws/operators/redshift_data.py", line 124, in execute
    self.statement_id = self.hook.execute_query(
  File "/home/airflow/.local/lib/python3.8/site-packages/airflow/providers/amazon/aws/hooks/redshift_data.py", line 99, in execute_query
    resp = self.conn.execute_statement(**trim_none_values(kwargs))
  File "/home/airflow/.local/lib/python3.8/site-packages/botocore/client.py", line 535, in _api_call
    return self._make_api_call(operation_name, kwargs)
  File "/home/airflow/.local/lib/python3.8/site-packages/botocore/client.py", line 963, in _make_api_call
    http, parsed_response = self._make_request(
  File "/home/airflow/.local/lib/python3.8/site-packages/botocore/client.py", line 986, in _make_request
    return self._endpoint.make_request(operation_model, request_dict)
  File "/home/airflow/.local/lib/python3.8/site-packages/botocore/endpoint.py", line 119, in make_request
    return self._send_request(request_dict, operation_model)
  File "/home/airflow/.local/lib/python3.8/site-packages/botocore/endpoint.py", line 198, in _send_request
    request = self.create_request(request_dict, operation_model)
  File "/home/airflow/.local/lib/python3.8/site-packages/botocore/endpoint.py", line 134, in create_request
    self._event_emitter.emit(
  File "/home/airflow/.local/lib/python3.8/site-packages/botocore/hooks.py", line 412, in emit
    return self._emitter.emit(aliased_event_name, **kwargs)
  File "/home/airflow/.local/lib/python3.8/site-packages/botocore/hooks.py", line 256, in emit
    return self._emit(event_name, kwargs)
  File "/home/airflow/.local/lib/python3.8/site-packages/botocore/hooks.py", line 239, in _emit
    response = handler(**kwargs)
  File "/home/airflow/.local/lib/python3.8/site-packages/botocore/signers.py", line 105, in handler
    return self.sign(operation_name, request)
  File "/home/airflow/.local/lib/python3.8/site-packages/botocore/signers.py", line 189, in sign
    auth.add_auth(request)
  File "/home/airflow/.local/lib/python3.8/site-packages/botocore/auth.py", line 418, in add_auth
    raise NoCredentialsError()
botocore.exceptions.NoCredentialsError: Unable to locate credentials
[2024-01-27T00:00:03.552+0000] {taskinstance.py:1400} INFO - Marking task as FAILED. dag_id=test_dag, task_id=test_redshift, execution_date=20240126T000000, start_date=20240127T000001, end_date=20240127T000003
[2024-01-27T00:00:03.557+0000] {standard_task_runner.py:104} ERROR - Failed to execute job 389 for task test_redshift (Unable to locate credentials; 5149)
[2024-01-27T00:00:03.604+0000] {local_task_job_runner.py:228} INFO - Task exited with return code 1
[2024-01-27T00:00:03.614+0000] {taskinstance.py:2778} INFO - 0 downstream tasks scheduled from follow-on schedule check
